Workbook
Name ____________tv1: #REF!,#REF!,#REF!,#REF!
Name ________tv1: #REF!,#REF!,#REF!,#REF!
Name _______PUB1: [1]profili!#REF!
Name _______RAI1: [1]profili!#REF!
Name _______TOT1: [1]profili!#REF!
Name ______PUB1: [1]profili!#REF!
Name ______RAI1: [1]profili!#REF!
Name ______TOT1: [1]profili!#REF!
Name ______tv1: #REF!,#REF!,#REF!,#REF!
Name _____PUB1: [1]profili!#REF!
Name _____RAI1: [1]profili!#REF!
Name _____TOT1: [1]profili!#REF!
Name _____tv1: #REF!,#REF!,#REF!,#REF!
Name ____PUB1: [1]profili!#REF!
Name ____RAI1: [1]profili!#REF!
Name ____TOT1: [1]profili!#REF!
Name ____tv1: #REF!,#REF!,#REF!,#REF!
Name ___DE2: {"'vert'!$A$1:$T$117"}
Name ___DE2: {"'vert'!$A$1:$T$117"}
Name ___PUB1: [1]profili!#REF!
Name ___RAI1: [1]profili!#REF!
Name ___TOT1: [1]profili!#REF!
Name ___tv1: #REF!,#REF!,#REF!,#REF!
Name __bla2: {"'vert'!$A$1:$T$117"}
Name __bla2: {"'vert'!$A$1:$T$117"}
Name __bla3: {"'vert'!$A$1:$T$117"}
Name __bla3: {"'vert'!$A$1:$T$117"}
Name __DE2: {"'vert'!$A$1:$T$117"}
Name __DE2: {"'vert'!$A$1:$T$117"}
Name __PUB1: [1]profili!#REF!
Name __RAI1: [1]profili!#REF!
Name __TOT1: [1]profili!#REF!
Name __TP1: '[2]MDL-1'!#REF!
Name __TP2: '[2]MDL-1'!#REF!
Name __TP3: '[2]MDL-1'!#REF!
Name __TP4: '[2]MDL-1'!#REF!
Name __tv1: #REF!,#REF!,#REF!,#REF!
Name _bdm.06B8576461724687B15495CCF2DD06E0.edm: '[3]MP Graphs'!$A:$IV
Name _bdm.06B8576461724687B15495CCF2DD06E0.edm: '[4]MP Graphs'!$A:$IV
Name _bdm.06CC246E7DBC44F3891086B0B75ECF39.edm: [3]WC!$A:$IV
Name _bdm.06CC246E7DBC44F3891086B0B75ECF39.edm: [4]WC!$A:$IV
Name _bdm.085CB1B4AFBC42FDB42A5D410DA22E65.edm: '[3]MP Graphs'!$A:$IV
Name _bdm.085CB1B4AFBC42FDB42A5D410DA22E65.edm: '[4]MP Graphs'!$A:$IV
Name _bdm.0AA3D3092EDA456BB97F68C1B69FBC0E.edm: '[3]MP Graphs'!$A:$IV
Name _bdm.0AA3D3092EDA456BB97F68C1B69FBC0E.edm: '[4]MP Graphs'!$A:$IV
Name _bdm.0D137C94AC1C4DB4AEA072BD9676C77E.edm: '[3]MP Graphs'!$A:$IV
Name _bdm.0D137C94AC1C4DB4AEA072BD9676C77E.edm: '[4]MP Graphs'!$A:$IV
Name _bdm.0F23163E1CA64A2FBCBA9851AE098750.edm: '[5]Graph by Product Type'!$A:$IV
Name _bdm.0F23163E1CA64A2FBCBA9851AE098750.edm: '[6]Graph by Product Type'!$A:$IV
Name _bdm.18D0F9FB523E4927A980C655ECF3F2B1.edm: '[3]MP Graphs'!$A:$IV
Name _bdm.18D0F9FB523E4927A980C655ECF3F2B1.edm: '[4]MP Graphs'!$A:$IV
Name _bdm.1F8BDD7AC78B4114B81FEF6970DA0ED6.edm: '[3]MP Graphs'!$A:$IV
Name _bdm.1F8BDD7AC78B4114B81FEF6970DA0ED6.edm: '[4]MP Graphs'!$A:$IV
Name _bdm.26049B46ED9A4A328BE14263914D3C5A.edm: '[3]MP Graphs'!$A:$IV
Name _bdm.26049B46ED9A4A328BE14263914D3C5A.edm: '[4]MP Graphs'!$A:$IV
Name _bdm.2A503CEAE4CE48ACB7D5A43D2AD392FD.edm: '[7]MP Graphs'!$A:$IV
Name _bdm.2A503CEAE4CE48ACB7D5A43D2AD392FD.edm: '[8]MP Graphs'!$A:$IV
Name _bdm.2E540CED84464485B2A6ED57DA28374B.edm: '[7]MP Graphs'!$A:$IV
Name _bdm.2E540CED84464485B2A6ED57DA28374B.edm: '[8]MP Graphs'!$A:$IV
Name _bdm.2E93E12EA5C047BC9FAD15B9E28B275A.edm: '[7]MP Graphs'!$A:$IV

Sheet Approval Form
K4: Company Name | L4: Universal Media Company (Single Partner Company with Limited Liability) | M4: Company Universal Media
B5: Client: | C5: LOC | K5: COMPANY ADDRESS | L5: MAWHIBA CENTER, OLAYA STREET, 2ND FLOOR, PO BOX 53034, RIYADH 11583 KINGDOM OF SAUDI ARABIA
B6: Campaign : | C6: Gulf Cup | K6: VAT REGISTRATION | L6: 312049011310003 | M6: TIN: 3130381549
B7: Market: | C7: KSA, GCC, Iraq, Yemen | K7: VAT % FROM JULY 1ST 2020 | L7: 0.15
B8: Media: | C8: Digital | K8: IBAN | L8: SA5445000000017396318001 | M8: SA5445000000017396318001
B9: reference # | C9: -
B10: Campaign code: | C10: -
B11: Date: | C11: =TODAY() -> 46258
B13: MEDIA PLAN DESCRIPTION | D13: Phase | E13: Market | G13: MEDIUM | H13: MP Cost- ( USD ) | I13: MP Cost- ( SAR )
B15: ATTENTION: | D15: Phase 1 - Aug - Sept (Launch) | E15: KSA | G15: ='Phase 1 - Aug - Sept (Launch)'!B18 -> META | H15: ='Phase 1 - Aug - Sept (Launch)'!Y18 -> 16000 | I15: =H15*3.76 -> 60160
B16: MARKET: | C16: =C7 -> KSA, GCC, Iraq, Yemen | G16: ='Phase 1 - Aug - Sept (Launch)'!B19 -> TikTok | H16: ='Phase 1 - Aug - Sept (Launch)'!Y19 -> 18720 | I16: =H16*3.76 -> 70387.2
B17: CLIENT: | C17: =C6 -> Gulf Cup | G17: ='Phase 1 - Aug - Sept (Launch)'!B20 -> Snapchat | H17: ='Phase 1 - Aug - Sept (Launch)'!Y20 -> 17150 | I17: =H17*3.76 -> 64484
G18: ='Phase 1 - Aug - Sept (Launch)'!B21 -> Snapchat First Commercial Takeover | H18: ='Phase 1 - Aug - Sept (Launch)'!Y21 -> 17000 | I18: =H18*3.76 -> 63920
G19: ='Phase 1 - Aug - Sept (Launch)'!B22 -> X | H19: ='Phase 1 - Aug - Sept (Launch)'!Y22 -> 15000 | I19: =H19*3.76 -> 56400
G20: ='Phase 1 - Aug - Sept (Launch)'!B23 -> X Takeover | H20: ='Phase 1 - Aug - Sept (Launch)'!Y23 -> 58493 | I20: =H20*3.76 -> 219933.68
G21: ='Phase 1 - Aug - Sept (Launch)'!B24 -> YouTube | H21: ='Phase 1 - Aug - Sept (Launch)'!Y24 -> 25000 | I21: =H21*3.76 -> 94000
G22: ='Phase 1 - Aug - Sept (Launch)'!B25 -> Programmatic | H22: ='Phase 1 - Aug - Sept (Launch)'!Y25 -> 45000 | I22: =H22*3.76 -> 169200
G23: ='Phase 1 - Aug - Sept (Launch)'!B26 -> Google Search | H23: ='Phase 1 - Aug - Sept (Launch)'!Y26 -> 7000 | I23: =H23*3.76 -> 26320
G24: ='Phase 1 - Aug - Sept (Launch)'!B27 -> Google Pmax | H24: ='Phase 1 - Aug - Sept (Launch)'!Y27 -> 11000 | I24: =H24*3.76 -> 41360
G25: ='Phase 1 - Aug - Sept (Launch)'!B28 -> META | H25: ='Phase 1 - Aug - Sept (Launch)'!Y28 -> 20000 | I25: =H25*3.76 -> 75200
G26: ='Phase 1 - Aug - Sept (Launch)'!B29 -> TikTok | H26: ='Phase 1 - Aug - Sept (Launch)'!Y29 -> 20000 | I26: =H26*3.76 -> 75200 | L26: SIGNATURES OF APPROVAL
E27: GCC | G27: ='Phase 1 - Aug - Sept (Launch)'!B33 -> META | H27: ='Phase 1 - Aug - Sept (Launch)'!Y33 -> 15000 | I27: =H27*3.76 -> 56400
G28: ='Phase 1 - Aug - Sept (Launch)'!B34 -> YouTube | H28: ='Phase 1 - Aug - Sept (Launch)'!Y34 -> 14000 | I28: =H28*3.76 -> 52640 | L28: UM MANAGER
G29: ='Phase 1 - Aug - Sept (Launch)'!B35 -> Programmatic | H29: ='Phase 1 - Aug - Sept (Launch)'!Y35 -> 14000 | I29: =H29*3.76 -> 52640
G30: ='Phase 1 - Aug - Sept (Launch)'!B36 -> Google Pmax | H30: ='Phase 1 - Aug - Sept (Launch)'!Y36 -> 12000 | I30: =H30*3.76 -> 45120
E31: Iraq | G31: ='Phase 1 - Aug - Sept (Launch)'!B40 -> META | H31: ='Phase 1 - Aug - Sept (Launch)'!Y40 -> 5000 | I31: =H31*3.76 -> 18800
G32: ='Phase 1 - Aug - Sept (Launch)'!B41 -> YouTube | H32: ='Phase 1 - Aug - Sept (Launch)'!Y41 -> 7000 | I32: =H32*3.76 -> 26320
G33: ='Phase 1 - Aug - Sept (Launch)'!B42 -> Google Pmax | H33: ='Phase 1 - Aug - Sept (Launch)'!Y42 -> 5000 | I33: =H33*3.76 -> 18800
E34: Yemen | G34: ='Phase 1 - Aug - Sept (Launch)'!B46 -> META | H34: ='Phase 1 - Aug - Sept (Launch)'!Y46 -> 5600 | I34: =H34*3.76 -> 21056
G35: ='Phase 1 - Aug - Sept (Launch)'!B47 -> YouTube | H35: ='Phase 1 - Aug - Sept (Launch)'!Y47 -> 4000 | I35: =H35*3.76 -> 15040
G36: ='Phase 1 - Aug - Sept (Launch)'!B48 -> Google Pmax | H36: ='Phase 1 - Aug - Sept (Launch)'!Y48 -> 6000 | I36: =H36*3.76 -> 22560
E37: Total (Phase 1) | H37: =SUM(H15:H36) -> 357963 | I37: =SUM(I15:I36) -> 1345940.9
D38: Song and Mascot Promotion | E38: KSA | G38: ='Song and Mascot Promotion'!B18 -> Snapchat | H38: ='Song and Mascot Promotion'!Z18 -> 35000 | I38: =H38*3.76 -> 131600
G39: ='Song and Mascot Promotion'!B19 -> YouTube | H39: ='Song and Mascot Promotion'!Z19 -> 20000 | I39: =H39*3.76 -> 75200
G40: ='Song and Mascot Promotion'!B20 -> Programmatic (Anghami) | H40: ='Song and Mascot Promotion'!Z20 -> 20000 | I40: =H40*3.76 -> 75200
G41: ='Song and Mascot Promotion'!B21 -> Programmatic (TMV) | H41: ='Song and Mascot Promotion'!Z21 -> 10000 | I41: =H41*3.76 -> 37600
E42: GCC | G42: {='Song and Mascot Promotion'!B25:B27} -> Programmatic (Spotify) Song Promotion | H42: ='Song and Mascot Promotion'!Z25 -> 13000 | I42: =H42*3.76 -> 48880
G43: Programmatic (Spotify) Mascot Promotion - Video | H43: ='Song and Mascot Promotion'!Z26 -> 10000 | I43: =H43*3.76 -> 37600
G44: Programmatic (Spotify) Mascot Promotion - Display | H44: ='Song and Mascot Promotion'!Z27 -> 9000 | I44: =H44*3.76 -> 33840
G45: ='Song and Mascot Promotion'!B28 -> Programmatic (TMV) | H45: ='Song and Mascot Promotion'!Z28 -> 7000 | I45: =H45*3.76 -> 26320
...

Sheet Phase 1 - Aug - Sept (Launch)
B6: Client: | C6: LOC
B7: Campaign : | C7: Gulf Cup
B8: Market: | C8: KSA, GCC, Iraq, Yemen
B9: Media: | C9: Digital
B10: reference # | C10: -
B11: PO: | C11: ='[36]Approval Form'!C10 -> #REF!
B12: Date: | C12: =TODAY() -> 46258
B14: PLATFORM | C14: PLACEMENT | D14: TARGET MARKET | E14: VIDEO DURATION | F14: DEVICE | G14: OBJECTIVE | H14: MEDIA BUY TYPE | I14: LANGUAGE | J14: AUDIENCE SEGMENT / TACTIC | K14: AUDIENCE SIZE | L14: Reach % | M14: Est. Reach | N14: Est. Frequency | O14: AD / CREATIVE | P14: DURATION | R14: BOOKED UNITS | S14: VTR | T14: VIDEO VIEWS | U14: CLICKS | W14: IMPRESSIONS | X14: NET UNIT COST | Y14: Total Cost ( USD ) | Z14: Cost ( SAR )
O15: FORMAT
B17: KSA
B18: META | C18: Feed | D18: KSA | E18: 6s + 15s | F18: CROSS DEVICE | G18: Awareness | H18: CPM | I18: English + Arabic | J18: Age:18-55 People who match: Interests: Football, Saudi Soccer League,Association Football, All Soccer fans, Soccer Match Events: Multi Sport Events, Live Matches Behavior: Soccer Fans Medium & High Content Engagement Keywords: Gulf Cup, Soccer, Champions League | K18: 19000000 | L18: =M18/K18 -> 0.84210526 | M18: =W18/N18 -> 16000000 | N18: 2 | O18: Video | P18: Aug 1 | Q18: Sept 15 | R18: =W18 -> 32000000 | S18: 0.02 | T18: =R18*S18 -> 640000 | U18: =W18*0.1% -> 32000 | W18: =(Y18*1000)/X18 -> 32000000 | X18: 0.5 | Y18: 16000 | Z18: =Y18*3.76 -> 60160 | AA18: =Z18/3.76 -> 16000 | AB18: =AA18*0.55 -> 8800 | AC18: =AA18-AB18 -> 7200
B19: TikTok | C19: Top Feed | D19: KSA | E19: 6s + 15s | F19: MOBILE | G19: Awareness | H19: CPM | I19: English + Arabic | J19: Age:18-55 People who match: Interests: Football, Saudi Soccer League,Association Football, All Soccer fans, Soccer Match Events: Multi Sport Events, Live Matches Behavior: Soccer Fans Medium & High Content Engagement Keywords: Gulf Cup, Soccer, Champions League | K19: 26000000 | L19: 0.3 | M19: =K19*L19 -> 7800000 | N19: 2 | O19: Video | P19: TBD | Q19: TBD | R19: =W19 -> 15600000 | S19: 0.04 | T19: =R19*S19 -> 624000 | U19: =W19*0.1% -> 15600 | W19: =M19*N19 -> 15600000 | X19: 1.2 | Y19: =(W19*X19)/1000 -> 18720 | Z19: =Y19*3.76 -> 70387.2 | AA19: =Z19/3.76 -> 18720
B20: Snapchat | C20: Feed | D20: KSA | E20: 6s + 15s | F20: MOBILE | G20: Awareness | H20: CPM | I20: English + Arabic | J20: Age:18-55 People who match: Interests: Football, Saudi Soccer League,Association Football, All Soccer fans, Soccer Match Events: Multi Sport Events, Live Matches Behavior: Soccer Fans Medium & High Content Engagement Keywords: Gulf Cup, Soccer, Champions League | K20: 12000000 | L20: =M20/K20 -> 0.47638889 | M20: =W20/N20 -> 5716666.7 | N20: 2 | O20: Video | P20: Aug 1 | Q20: Sept 15 | R20: =W20 -> 11433333 | S20: 0.02 | T20: =R20*S20 -> 228666.67 | U20: =W20*0.1% -> 11433.333 | W20: =(Y20*1000)/X20 -> 11433333 | X20: 1.5 | Y20: 17150 | Z20: =Y20*3.76 -> 64484 | AA20: =Z20/3.76 -> 17150 | AB20: =AA20*0.6 -> 10290 | AC20: =AA20-AB20 -> 6860
B21: Snapchat First Commercial Takeover | C21: First Commercial | D21: KSA | E21: 6s | F21: MOBILE | G21: Awareness | H21: CPM | I21: Arabic | J21: Mass | K21: 24000000 | L21: 0.35 | M21: =K21*L21 -> 8400000 | N21: 3 | O21: Video | P21: May 16 | Q21: May 16 | R21: =W21 -> 2500000 | S21: 0.8 | T21: =R21*S21 -> 2000000 | U21: - | W21: 2500000 | X21: FIXED | Y21: 17000 | Z21: =Y21*3.76 -> 63920 | AA21: =Z21/3.76 -> 17000
B22: X | C22: Feed | D22: KSA | E22: 6s + 15s | F22: MOBILE | G22: Awareness | H22: CPM | I22: English + Arabic | J22: Age:18-55 People who match: Interests: Football, Saudi Soccer League,Association Football, All Soccer fans, Soccer Match Events: Multi Sport Events, Live Matches Behavior: Soccer Fans Medium & High Content Engagement Keywords: Gulf Cup, Soccer, Champions League | K22: 8000000 | L22: =M22/K22 -> 1.0416667 | M22: =W22/N22 -> 8333333.3 | N22: 2 | O22: Video | P22: Aug 1 | Q22: Sept 15 | R22: =W22 -> 16666667 | S22: 0.02 | T22: =R22*S22 -> 333333.33 | U22: =W22*0.1% -> 16666.667 | W22: =(Y22*1000)/X22 -> 16666667 | X22: 0.9 | Y22: 15000 | Z22: =Y22*3.76 -> 56400 | AA22: =Z22/3.76 -> 15000
B23: X Takeover | C23: Takeover | D23: KSA | E23: 6s | F23: CROSS DEVICE | G23: Awareness | H23: FIXED | I23: Arabic | J23: Mass | K23: 19000000 | L23: - | M23: - | N23: - | O23: Video | P23: TBD | Q23: TBD | R23: - | S23: - | T23: - | U23: - | W23: 22000000 | X23: FIXED | Y23: 58493 | Z23: =Y23*3.76 -> 219933.68 | AA23: =Z23/3.76 -> 58493
B24: YouTube | C24: VRC | D24: KSA | E24: 6s + 15s | F24: CROSS DEVICE | G24: Awareness | H24: CPM | I24: English + Arabic | J24: Age:18-55 People who match: Interests: Football, Saudi Soccer League,Association Football, All Soccer fans, Soccer Match Events: Multi Sport Events, Live Matches Behavior: Soccer Fans Medium & High Content Engagement Keywords: Gulf Cup, Soccer, Champions League | K24: 19000000 | L24: =M24/K24 -> 0.54824561 | M24: =W24/N24 -> 10416667 | N24: 2 | O24: Video | P24: Aug 1 | Q24: Sept 15 | R24: =W24 -> 20833333 | S24: 0.2 | T24: =R24*S24 -> 4166666.7 | U24: - | W24: =(Y24*1000)/X24 -> 20833333 | X24: 1.2 | Y24: 25000 | Z24: =Y24*3.76 -> 94000 | AA24: =Z24/3.76 -> 25000
B25: Programmatic | C25: Premium sports websites | D25: KSA | E25: Static | F25: CROSS DEVICE | G25: Website Traffic | H25: CPM | I25: English + Arabic | J25: Age:18-55 People who match: Interests: Football, Saudi Soccer League,Association Football, All Soccer fans, Soccer Match Events: Multi Sport Events, Live Matches Behavior: Soccer Fans Medium & High Content Engagement Keywords: Gulf Cup, Soccer, Champions League | K25: - | L25: - | M25: - | N25: - | O25: Static | P25: Aug 1 | Q25: Sept 15 | R25: =W25 -> 12857143 | S25: - | T25: - | U25: =W25*1% -> 128571.43 | W25: =(Y25*1000)/X25 -> 12857143 | X25: 3.5 | Y25: 45000 | Z25: =Y25*3.76 -> 169200 | AA25: =Z25/3.76 -> 45000
B26: Google Search | C26: Search Network | D26: KSA | E26: - | F26: CROSS DEVICE | G26: Website Traffic | H26: CPC | I26: English + Arabic | J26: Age:18-55 People who match: Interests: Football, Saudi Soccer League,Association Football, All Soccer fans, Soccer Match Events: Multi Sport Events, Live Matches Behavior: Soccer Fans Medium & High Content Engagement Keywords: Gulf Cup, Soccer, Champions League | K26: - | L26: - | M26: - | N26: - | O26: Dynamic Ads | P26: Aug 1 | Q26: Sept 15 | R26: =U26 -> 5833.3333 | S26: - | T26: - | U26: =Y26/X26 -> 5833.3333 | W26: - | X26: 1.2 | Y26: 7000 | Z26: =Y26*3.76 -> 26320 | AA26: =Z26/3.76 -> 7000
B27: Google Pmax | C27: PMAX | D27: KSA | E27: - | F27: CROSS DEVICE | G27: Ticket Sales | H27: CPC | I27: English + Arabic | J27: Age:18-55 People who match: Interests: Football, Saudi Soccer League,Association Football, All Soccer fans, Soccer Match Events: Multi Sport Events, Live Matches Behavior: Soccer Fans Medium & High Content Engagement Keywords: Gulf Cup, Soccer, Champions League | K27: - | L27: - | M27: - | N27: - | O27: Dynamic Ads | P27: Aug 1 | Q27: Sept 15 | R27: =U27 -> 27500 | S27: - | T27: - | U27: =Y27/X27 -> 27500 | W27: - | X27: 0.4 | Y27: 11000 | Z27: =Y27*3.76 -> 41360 | AA27: =Z27/3.76 -> 11000
B28: META | C28: Feed | D28: KSA | E28: 6s + 15s | F28: CROSS DEVICE | G28: Ticket Sales | H28: CPC | I28: English + Arabic | J28: Age:18-55 People who match: Interests: Football, Saudi Soccer League,Association Football, All Soccer fans, Soccer Match Events: Multi Sport Events, Live Matches Behavior: Soccer Fans Medium & High Content Engagement Keywords: Gulf Cup, Soccer, Champions League | K28: 19000000 | L28: - | M28: - | N28: - | O28: Video | P28: Aug 1 | Q28: Sept 15 | R28: =U28 -> 50000 | S28: - | T28: - | U28: =Y28/X28 -> 50000 | W28: - | X28: 0.4 | Y28: 20000 | Z28: =Y28*3.76 -> 75200 | AA28: =Z28/3.76 -> 20000
B29: TikTok | C29: Feed | D29: KSA | E29: 6s + 15s | F29: CROSS DEVICE | G29: Ticket Sales | H29: CPC | I29: English + Arabic | J29: Age:18-55 People who match: Interests: Football, Saudi Soccer League,Association Football, All Soccer fans, Soccer Match Events: Multi Sport Events, Live Matches Behavior: Soccer Fans Medium & High Content Engagement Keywords: Gulf Cup, Soccer, Champions League | K29: 21000000 | L29: - | M29: - | N29: - | O29: Video | P29: Aug 1 | Q29: Sept 15 | R29: =U29 -> 66666.667 | S29: - | T29: - | U29: =Y29/X29 -> 66666.667 | W29: - | X29: 0.3 | Y29: 20000 | Z29: =Y29*3.76 -> 75200 | AA29: =Z29/3.76 -> 20000
B30: Total (KSA) | T30: =SUM(T18:T29) -> 7992666.7 | U30: =SUM(U18:U29) -> 354271.43 | W30: =SUM(W18:W29) -> 1.3389048e+08 | Y30: =SUM(Y18:Y29) -> 270363 | Z30: =SUM(Z18:Z29) -> 1016564.9 | AA30: =Z30/3.76 -> 270363
B32: GCC
B33: META | C33: Feed | D33: UAE, Oman, Kuwait, Qatar, Bahrain | E33: 6s + 15s | F33: CROSS DEVICE | G33: Awareness | H33: CPM | I33: English + Arabic | J33: Age:18-55 People who match: Interests: Football, Saudi Soccer League,Association Football, All Soccer fans, Soccer Match Events: Multi Sport Events, Live Matches Behavior: Soccer Fans Medium & High Content Engagement Keywords: Gulf Cup, Soccer, Champions League | K33: 16000000 | L33: =M33/K33 -> 0.66964286 | M33: =W33/N33 -> 10714286 | N33: 2 | O33: Video | P33: Aug 1 | Q33: Sept 15 | R33: =W33 -> 21428571 | S33: 0.02 | T33: =R33*S33 -> 428571.43 | U33: =W33*0.1% -> 21428.571 | W33: =(Y33*1000)/X33 -> 21428571 | X33: 0.7 | Y33: 15000 | Z33: =Y33*3.76 -> 56400
B34: YouTube | C34: Feed | D34: UAE, Oman, Kuwait, Qatar, Bahrain | E34: 6s + 15s | F34: CROSS DEVICE | G34: Awareness | H34: CPM | I34: English + Arabic | K34: 13500000 | L34: =M34/K34 -> 0.43209877 | M34: =W34/N34 -> 5833333.3 | N34: 2 | O34: Video | P34: Aug 1 | Q34: Sept 15 | R34: =W34 -> 11666667 | S34: 0.2 | T34: =R34*S34 -> 2333333.3 | U34: - | W34: =(Y34*1000)/X34 -> 11666667 | X34: 1.2 | Y34: 14000 | Z34: =Y34*3.76 -> 52640
B35: Programmatic | C35: Premium sports websites | D35: UAE, Oman, Kuwait, Qatar, Bahrain | E35: Static | F35: CROSS DEVICE | G35: Website Traffic | H35: CPM | I35: English + Arabic | K35: - | L35: - | M35: - | N35: - | O35: Static | P35: Aug 1 | Q35: Sept 15 | R35: =W35 -> 4000000 | S35: - | T35: - | U35: =W35*1% -> 40000 | W35: =(Y35*1000)/X35 -> 4000000 | X35: 3.5 | Y35: 14000 | Z35: =Y35*3.76 -> 52640
B36: Google Pmax | C36: PMAX | D36: UAE, Oman, Kuwait, Qatar, Bahrain | E36: - | F36: CROSS DEVICE | G36: Ticket Sales | H36: CPC | I36: English + Arabic | K36: - | L36: - | M36: - | N36: - | O36: Dynamic Ads | P36: Aug 1 | Q36: Sept 15 | R36: =U36 -> 30000 | S36: - | T36: - | U36: =Y36/X36 -> 30000 | W36: - | X36: 0.4 | Y36: 12000 | Z36: =Y36*3.76 -> 45120
B37: Total (GCC) | T37: =SUM(T33:T36) -> 2761904.8 | U37: =SUM(U33:U36) -> 91428.571 | W37: =SUM(W33:W34) -> 33095238 | Y37: =SUM(Y33:Y36) -> 55000 | Z37: =SUM(Z33:Z36) -> 206800
B39: Iraq
B40: META | C40: Feed | D40: Iraq | E40: 6s + 15s | F40: CROSS DEVICE | G40: Awareness | H40: CPM | I40: Arabic | J40: Age:18-55 People who match: Interests: Football, Saudi Soccer League,Association Football, All Soccer fans, Soccer Match Events: Multi Sport Events, Live Matches Behavior: Soccer Fans Medium & High Content Engagement Keywords: Gulf Cup, Soccer, Champions League | K40: 22000000 | L40: =M40/K40 -> 0.15151515 | M40: =W40/N40 -> 3333333.3 | N40: 2 | O40: Video | P40: Aug 1 | Q40: Sept 15 | R40: =W40 -> 6666666.7 | S40: 0.02 | T40: =R40*S40 -> 133333.33 | U40: =W40*0.1% -> 6666.6667 | W40: =(Y40*1000)/X40 -> 6666666.7 | X40: 0.75 | Y40: 5000 | Z40: =Y40*3.76 -> 18800
B41: YouTube | C41: Feed | D41: Iraq | E41: 6s + 15s | F41: CROSS DEVICE | G41: Awareness | H41: CPM | I41: Arabic | K41: 19000000 | L41: =M41/K41 -> 0.15350877 | M41: =W41/N41 -> 2916666.7 | N41: 2 | O41: Video | P41: Aug 1 | Q41: Sept 15 | R41: =W41 -> 5833333.3 | S41: 0.2 | T41: =R41*S41 -> 1166666.7 | U41: - | W41: =(Y41*1000)/X41 -> 5833333.3 | X41: 1.2 | Y41: 7000 | Z41: =Y41*3.76 -> 26320
B42: Google Pmax | C42: PMAX | D42: Iraq | E42: - | F42: CROSS DEVICE | G42: Ticket Sales | H42: CPC | I42: Arabic | K42: - | L42: - | M42: - | N42: - | O42: Dynamic Ads | P42: Aug 1 | Q42: Sept 15 | R42: =U42 -> 12500 | S42: - | T42: - | U42: =Y42/X42 -> 12500 | W42: - | X42: 0.4 | Y42: 5000 | Z42: =Y42*3.76 -> 18800
B43: Total (Iraq) | T43: =SUM(T40:T42) -> 1300000 | U43: =SUM(U40:U42) -> 19166.667 | W43: =SUM(W40:W41) -> 12500000 | Y43: =SUM(Y40:Y42) -> 17000 | Z43: =SUM(Z40:Z42) -> 63920
B45: Yemen
B46: META | C46: Feed | D46: Yemen | E46: 6s + 15s | F46: CROSS DEVICE | G46: Awareness | H46: CPM | I46: Arabic | J46: Age:18-55 People who match: Interests: Football, Saudi Soccer League,Association Football, All Soccer fans, Soccer Match Events: Multi Sport Events, Live Matches Behavior: Soccer Fans Medium & High Content Engagement Keywords: Gulf Cup, Soccer, Champions League | K46: 3000000 | L46: =M46/K46 -> 1.2444444 | M46: =W46/N46 -> 3733333.3 | N46: 2 | O46: Video | P46: Aug 1 | Q46: Sept 15 | R46: =W46 -> 7466666.7 | S46: 0.02 | T46: =R46*S46 -> 149333.33 | U46: =W46*0.1% -> 7466.6667 | W46: =(Y46*1000)/X46 -> 7466666.7 | X46: 0.75 | Y46: 5600 | Z46: =Y46*3.76 -> 21056
B47: YouTube | C47: Feed | D47: Yemen | E47: 6s + 15s | F47: CROSS DEVICE | G47: Awareness | H47: CPM | I47: Arabic | K47: 4500000 | L47: =M47/K47 -> 0.37037037 | M47: =W47/N47 -> 1666666.7 | N47: 2 | O47: Video | P47: Aug 1 | Q47: Sept 15 | R47: =W47 -> 3333333.3 | S47: 0.2 | T47: =R47*S47 -> 666666.67 | U47: - | W47: =(Y47*1000)/X47 -> 3333333.3 | X47: 1.2 | Y47: 4000 | Z47: =Y47*3.76 -> 15040
B48: Google Pmax | C48: PMAX | D48: Yemen | E48: - | F48: CROSS DEVICE | G48: Ticket Sales | H48: CPC | I48: Arabic | K48: - | L48: - | M48: - | N48: - | O48: Dynamic Ads | P48: Aug 1 | Q48: Sept 15 | R48: =U48 -> 15000 | S48: - | T48: - | U48: =Y48/X48 -> 15000 | W48: - | X48: 0.4 | Y48: 6000 | Z48: =Y48*3.76 -> 22560
B49: Total (Yemen) | T49: =SUM(T46:T48) -> 816000 | U49: =SUM(U46:U48) -> 22466.667 | W49: =SUM(W46:W47) -> 10800000 | Y49: =SUM(Y46:Y48) -> 15600 | Z49: =SUM(Z46:Z48) -> 58656
B51: Grand Total (All Markets) | W51: =SUM(W30,W37) -> 1.6698571e+08 | Y51: =SUM(Y30,Y37,Y43,Y49) -> 357963 | Z51: =SUM(Z30,Z37,Z43,Z49) -> 1345940.9
...

Sheet Phase 2 - Sep - Oct
B6: Client: | C6: LOC
B7: Campaign : | C7: Gulf Cup
B8: Market: | C8: KSA, GCC, Iraq, Yemen
B9: Media: | C9: Digital
B10: reference # | C10: -
B11: PO: | C11: ='[36]Approval Form'!C10 -> #REF!
B12: Date: | C12: =TODAY() -> 46258
B14: PLATFORM | C14: PLACEMENT | D14: TARGET MARKET | E14: VIDEO DURATION | F14: DEVICE | G14: OBJECTIVE | H14: MEDIA BUY TYPE | I14: LANGUAGE | J14: AUDIENCE SEGMENT / TACTIC | K14: AUDIENCE SIZE | L14: Reach % | M14: Est. Reach | N14: Est. Frequency | O14: AD / CREATIVE | P14: DURATION | R14: BOOKED UNITS | S14: VTR | T14: VIDEO VIEWS | U14: CLICKS | W14: IMPRESSIONS | X14: NET UNIT COST | Y14: Total Cost ( USD ) | Z14: Cost ( SAR )
O15: FORMAT
B17: KSA
B18: META | C18: Feed | D18: KSA | E18: 6s + 15s | F18: CROSS DEVICE | G18: Awareness | H18: CPM | I18: English + Arabic | J18: Age:18-55 People who match: Interests: Football, Saudi Soccer League,Association Football, All Soccer fans, Soccer Match Events: Multi Sport Events, Live Matches Behavior: Soccer Fans Medium & High Content Engagement Keywords: Gulf Cup, Soccer, Champions League | K18: 19000000 | L18: =M18/K18 -> 0.94736842 | M18: =W18/N18 -> 18000000 | N18: 2 | O18: Video | P18: Sept 16 | Q18: Oct 6 | R18: =W18 -> 36000000 | S18: 0.02 | T18: =R18*S18 -> 720000 | U18: =W18*0.1% -> 36000 | W18: =(Y18*1000)/X18 -> 36000000 | X18: 0.5 | Y18: 18000 | Z18: =Y18*3.76 -> 67680
B19: TikTok | C19: Feed | D19: KSA | E19: 6s + 15s | F19: MOBILE | G19: Awareness | H19: CPM | I19: English + Arabic | K19: 21000000 | L19: =M19/K19 -> 0.71428571 | M19: =W19/N19 -> 15000000 | N19: 2 | O19: Video | P19: Sept 16 | Q19: Oct 6 | R19: =W19 -> 30000000 | S19: 0.02 | T19: =R19*S19 -> 600000 | U19: =W19*0.1% -> 30000 | W19: =(Y19*1000)/X19 -> 30000000 | X19: 0.6 | Y19: 18000 | Z19: =Y19*3.76 -> 67680
B20: Snapchat | C20: Feed | D20: KSA | E20: 6s + 15s | F20: MOBILE | G20: Awareness | H20: CPM | I20: English + Arabic | K20: 12000000 | L20: =M20/K20 -> 0.5 | M20: =W20/N20 -> 6000000 | N20: 2 | O20: Video | P20: Sept 16 | Q20: Oct 6 | R20: =W20 -> 12000000 | S20: 0.02 | T20: =R20*S20 -> 240000 | U20: =W20*0.1% -> 12000 | W20: =(Y20*1000)/X20 -> 12000000 | X20: 1.5 | Y20: 18000 | Z20: =Y20*3.76 -> 67680
B21: YouTube | C21: VRC | D21: KSA | E21: 6s + 15s | F21: CROSS DEVICE | G21: Awareness | H21: CPM | I21: English + Arabic | K21: 19000000 | L21: =M21/K21 -> 0.39473684 | M21: =W21/N21 -> 7500000 | N21: 2 | O21: Video | P21: Sept 16 | Q21: Oct 6 | R21: =W21 -> 15000000 | S21: 0.2 | T21: =R21*S21 -> 3000000 | U21: - | W21: =(Y21*1000)/X21 -> 15000000 | X21: 1.2 | Y21: 18000 | Z21: =Y21*3.76 -> 67680
B22: Programmatic | C22: Premium sports websites | D22: KSA | E22: Static | F22: CROSS DEVICE | G22: Website Traffic | H22: CPM | I22: English + Arabic | K22: - | L22: - | M22: - | N22: - | O22: Static | P22: Sept 16 | Q22: Oct 6 | R22: =W22 -> 11428571 | S22: - | T22: - | U22: =W22*1% -> 114285.71 | W22: =(Y22*1000)/X22 -> 11428571 | X22: 3.5 | Y22: 40000 | Z22: =Y22*3.76 -> 150400
B23: X | C23: Feed | D23: KSA | E23: 6s + 15s | F23: MOBILE | G23: Awareness | H23: CPM | I23: English + Arabic | K23: 8000000 | L23: =M23/K23 -> 1.1111111 | M23: =W23/N23 -> 8888888.9 | N23: 2 | O23: Video | P23: Sept 16 | Q23: Oct 6 | R23: =W23 -> 17777778 | S23: 0.02 | T23: =R23*S23 -> 355555.56 | U23: =W23*0.1% -> 17777.778 | W23: =(Y23*1000)/X23 -> 17777778 | X23: 0.9 | Y23: 16000 | Z23: =Y23*3.76 -> 60160
B24: Programmatic (Videx Gaming) | C24: Streamer Mention, Live chat Interaction, Polls, Voting​ Moment Marketing​ Leaderboard​ Innova​ Tower​ | D24: KSA | E24: Dynamic Ads | F24: CROSS DEVICE | G24: Awareness | H24: CPV | I24: English + Arabic | K24: - | L24: - | M24: - | N24: - | O24: Dynamic Ads | P24: Sept 16 | Q24: Oct 6 | R24: =W24 -> - | S24: - | T24: =Y24/X24 -> 350000 | U24: - | W24: - | X24: 0.04 | Y24: 14000 | Z24: =Y24*3.76 -> 52640
B25: Google | C25: Search Network | D25: KSA | E25: - | F25: CROSS DEVICE | G25: Website Traffic | H25: CPC | I25: English + Arabic | K25: - | L25: - | M25: - | N25: - | O25: Dynamic Ads | P25: Sept 16 | Q25: Oct 6 | R25: =U25 -> 10000 | S25: - | T25: - | U25: =Y25/X25 -> 10000 | W25: - | X25: 1.2 | Y25: 12000 | Z25: =Y25*3.76 -> 45120
B26: Google | C26: PMAX | D26: KSA | E26: - | F26: CROSS DEVICE | G26: Ticket Sales | H26: CPC | I26: English + Arabic | K26: - | L26: - | M26: - | N26: - | O26: Dynamic Ads | P26: Sept 16 | Q26: Oct 6 | R26: =U26 -> 30000 | S26: - | T26: - | U26: =Y26/X26 -> 30000 | W26: - | X26: 0.4 | Y26: 12000 | Z26: =Y26*3.76 -> 45120
B27: META | C27: Feed | D27: KSA | E27: 6s + 15s | F27: CROSS DEVICE | G27: Ticket Sales | H27: CPC | I27: English + Arabic | K27: 19000000 | L27: - | M27: - | N27: - | O27: Video | P27: Sept 16 | Q27: Oct 6 | R27: =U27 -> 32500 | S27: - | T27: - | U27: =Y27/X27 -> 32500 | W27: - | X27: 0.4 | Y27: 13000 | Z27: =Y27*3.76 -> 48880
B28: TikTok | C28: Feed | D28: KSA | E28: 6s + 15s | F28: CROSS DEVICE | G28: Ticket Sales | H28: CPC | I28: English + Arabic | K28: 21000000 | L28: - | M28: - | N28: - | O28: Video | P28: Sept 16 | Q28: Oct 6 | R28: =U28 -> 43333.333 | S28: - | T28: - | U28: =Y28/X28 -> 43333.333 | W28: - | X28: 0.3 | Y28: 13000 | Z28: =Y28*3.76 -> 48880
B29: Total (KSA) | T29: =SUM(T18:T28) -> 5265555.6 | U29: =SUM(U18:U28) -> 325896.83 | W29: =SUM(W18:W28) -> 1.2220635e+08 | Y29: =SUM(Y18:Y28) -> 192000 | Z29: =SUM(Z18:Z28) -> 721920
B31: GCC
B32: META | C32: Feed | D32: UAE, Oman, Kuwait, Qatar, Bahrain | E32: 6s + 15s | F32: CROSS DEVICE | G32: Awareness | H32: CPM | I32: English + Arabic | J32: Age:18-55 People who match: Interests: Football, Saudi Soccer League,Association Football, All Soccer fans, Soccer Match Events: Multi Sport Events, Live Matches Behavior: Soccer Fans Medium & High Content Engagement Keywords: Gulf Cup, Soccer, Champions League | K32: 16000000 | L32: =M32/K32 -> 0.26785714 | M32: =W32/N32 -> 4285714.3 | N32: 2 | O32: Video | P32: Sept 16 | Q32: Oct 6 | R32: =W32 -> 8571428.6 | S32: 0.02 | T32: =R32*S32 -> 171428.57 | U32: =W32*0.1% -> 8571.4286 | W32: =(Y32*1000)/X32 -> 8571428.6 | X32: 0.7 | Y32: 6000 | Z32: =Y32*3.76 -> 22560
B33: YouTube | C33: Feed | D33: UAE, Oman, Kuwait, Qatar, Bahrain | E33: 6s + 15s | F33: CROSS DEVICE | G33: Awareness | H33: CPM | I33: English + Arabic | K33: 13500000 | L33: =M33/K33 -> 0.24691358 | M33: =W33/N33 -> 3333333.3 | N33: 2 | O33: Video | P33: Sept 16 | Q33: Oct 6 | R33: =W33 -> 6666666.7 | S33: 0.2 | T33: =R33*S33 -> 1333333.3 | U33: - | W33: =(Y33*1000)/X33 -> 6666666.7 | X33: 1.2 | Y33: 8000 | Z33: =Y33*3.76 -> 30080
B34: Programmatic (Videx Gaming) | C34: Streamer Mention, Live chat Interaction, Polls, Voting​ Moment Marketing​ Leaderboard​ Innova​ Tower​ | D34: UAE, Oman, Kuwait, Qatar, Bahrain | E34: Dynamic Ads | F34: CROSS DEVICE | G34: Awareness | H34: CPV | I34: English + Arabic | K34: - | L34: - | M34: - | N34: - | O34: Dynamic Ads | P34: Sept 16 | Q34: Oct 6 | R34: =W34 -> - | S34: - | T34: =Y34/X34 -> 175000 | U34: - | W34: - | X34: 0.04 | Y34: 7000 | Z34: =Y34*3.76 -> 26320
B35: Google | C35: PMAX | D35: UAE, Oman, Kuwait, Qatar, Bahrain | E35: - | F35: CROSS DEVICE | G35: Ticket Sales | H35: CPC | I35: Arabic | K35: - | L35: - | M35: - | N35: - | O35: Dynamic Ads | P35: Sept 16 | Q35: Oct 6 | R35: =U35 -> 17500 | S35: - | T35: - | U35: =Y35/X35 -> 17500 | W35: - | X35: 0.4 | Y35: 7000 | Z35: =Y35*3.76 -> 26320
B36: Total (GCC) | T36: =SUM(T32:T35) -> 1679761.9 | U36: =SUM(U32:U35) -> 26071.429 | W36: =SUM(W32:W35) -> 15238095 | Y36: =SUM(Y32:Y35) -> 28000 | Z36: =SUM(Z32:Z35) -> 105280
B38: Iraq
B39: META | C39: Feed | D39: Iraq | E39: 6s + 15s | F39: CROSS DEVICE | G39: Awareness | H39: CPM | I39: Arabic | J39: Age:18-55 People who match: Interests: Football, Saudi Soccer League,Association Football, All Soccer fans, Soccer Match Events: Multi Sport Events, Live Matches Behavior: Soccer Fans Medium & High Content Engagement Keywords: Gulf Cup, Soccer, Champions League | K39: 22000000 | L39: =M39/K39 -> 0.15151515 | M39: =W39/N39 -> 3333333.3 | N39: 2 | O39: Video | P39: Sept 16 | Q39: Oct 6 | R39: =W39 -> 6666666.7 | S39: 0.02 | T39: =R39*S39 -> 133333.33 | U39: =W39*0.1% -> 6666.6667 | W39: =(Y39*1000)/X39 -> 6666666.7 | X39: 0.75 | Y39: 5000 | Z39: =Y39*3.76 -> 18800
B40: YouTube | C40: Feed | D40: Iraq | E40: 6s + 15s | F40: CROSS DEVICE | G40: Awareness | H40: CPM | I40: Arabic | K40: 19000000 | L40: =M40/K40 -> 0.087719298 | M40: =W40/N40 -> 1666666.7 | N40: 2 | O40: Video | P40: Sept 16 | Q40: Oct 6 | R40: =W40 -> 3333333.3 | S40: 0.2 | T40: =R40*S40 -> 666666.67 | U40: - | W40: =(Y40*1000)/X40 -> 3333333.3 | X40: 1.2 | Y40: 4000 | Z40: =Y40*3.76 -> 15040
B41: Programmatic (Videx Gaming) | C41: Streamer Mention, Live chat Interaction, Polls, Voting​ Moment Marketing​ Leaderboard​ Innova​ Tower​ | D41: Iraq | E41: Dynamic Ads | F41: CROSS DEVICE | G41: Awareness | H41: CPV | I41: English + Arabic | K41: - | L41: - | M41: - | N41: - | O41: Dynamic Ads | P41: Sept 16 | Q41: Oct 6 | R41: =W41 -> - | S41: - | T41: =Y41/X41 -> 125000 | U41: - | W41: - | X41: 0.04 | Y41: 5000 | Z41: =Y41*3.76 -> 18800
B42: Google | C42: PMAX | D42: Iraq | E42: - | F42: CROSS DEVICE | G42: Ticket Sales | H42: CPC | I42: Arabic | K42: - | L42: - | M42: - | N42: - | O42: Dynamic Ads | P42: Sept 16 | Q42: Oct 6 | R42: =U42 -> 8750 | S42: - | T42: - | U42: =Y42/X42 -> 8750 | W42: - | X42: 0.4 | Y42: 3500 | Z42: =Y42*3.76 -> 13160
B43: Total (Iraq) | T43: =SUM(T39:T42) -> 925000 | U43: =SUM(U39:U42) -> 15416.667 | W43: =SUM(W39:W40) -> 10000000 | Y43: =SUM(Y39:Y42) -> 17500 | Z43: =SUM(Z39:Z42) -> 65800
B45: Yemen
B46: META | C46: Feed | D46: Yemen | E46: 6s + 15s | F46: CROSS DEVICE | G46: Awareness | H46: CPM | I46: Arabic | J46: Age:18-55 People who match: Interests: Football, Saudi Soccer League,Association Football, All Soccer fans, Soccer Match Events: Multi Sport Events, Live Matches Behavior: Soccer Fans Medium & High Content Engagement Keywords: Gulf Cup, Soccer, Champions League | K46: 3000000 | L46: =M46/K46 -> 0.66666667 | M46: =W46/N46 -> 2000000 | N46: 2 | O46: Video | P46: Sept 16 | Q46: Oct 6 | R46: =W46 -> 4000000 | S46: 0.02 | T46: =R46*S46 -> 80000 | U46: =W46*0.1% -> 4000 | W46: =(Y46*1000)/X46 -> 4000000 | X46: 0.75 | Y46: 3000 | Z46: =Y46*3.76 -> 11280
B47: YouTube | C47: Feed | D47: Yemen | E47: 6s + 15s | F47: CROSS DEVICE | G47: Awareness | H47: CPM | I47: Arabic | K47: 4500000 | L47: =M47/K47 -> 0.27777778 | M47: =W47/N47 -> 1250000 | N47: 2 | O47: Video | P47: Sept 16 | Q47: Oct 6 | R47: =W47 -> 2500000 | S47: 0.2 | T47: =R47*S47 -> 500000 | U47: - | W47: =(Y47*1000)/X47 -> 2500000 | X47: 1.2 | Y47: 3000 | Z47: =Y47*3.76 -> 11280
B48: Google | C48: PMAX | D48: Yemen | E48: - | F48: CROSS DEVICE | G48: Ticket Sales | H48: CPC | I48: Arabic | K48: - | L48: - | M48: - | N48: - | O48: Dynamic Ads | P48: Sept 16 | Q48: Oct 6 | R48: =U48 -> 10000 | S48: - | T48: - | U48: =Y48/X48 -> 10000 | W48: - | X48: 0.4 | Y48: 4000 | Z48: =Y48*3.76 -> 15040
B49: Total (Yemen) | T49: =SUM(T46:T48) -> 580000 | U49: =SUM(U46:U48) -> 14000 | W49: =SUM(W46:W48) -> 6500000 | Y49: =SUM(Y46:Y48) -> 10000 | Z49: =SUM(Z46:Z48) -> 37600
B51: Grand Total (All Markets) | W51: =SUM(W29,W36) -> 1.3744444e+08 | Y51: =SUM(Y29,Y36,Y43,Y49) -> 247500 | Z51: =SUM(Z29,Z36,Z43,Z49) -> 930600
...

Sheet Song and Mascot Promotion
B6: Client: | C6: LOC
B7: Campaign : | C7: Gulf Cup
B8: Market: | C8: KSA, GCC, Iraq
B9: Media: | C9: Digital
B10: reference # | C10: -
B11: PO: | C11: ='[36]Approval Form'!C10 -> #REF!
B12: Date: | C12: =TODAY() -> 46258
B14: PLATFORM | C14: PLACEMENT | D14: OBJECTIVE | E14: TARGET MARKET | F14: VIDEO DURATION | G14: DEVICE | H14: OBJECTIVE | I14: MEDIA BUY TYPE | J14: LANGUAGE | K14: AUDIENCE SEGMENT / TACTIC | L14: AUDIENCE SIZE | M14: Reach % | N14: Est. Reach | O14: Est. Frequency | P14: AD / CREATIVE | Q14: DURATION | S14: BOOKED UNITS | T14: VTR | U14: VIDEO VIEWS | V14: CLICKS | X14: IMPRESSIONS | Y14: NET UNIT COST | Z14: Total Cost ( USD ) | AA14: Cost ( SAR )
P15: FORMAT
B17: KSA
B18: Snapchat | C18: AR Activation for official Mascot | D18: Mascot Promotion | E18: KSA | F18: 6s + 15s | G18: MOBILE | H18: Awareness | I18: CPM | J18: English + Arabic | L18: 12000000 | M18: =N18/L18 -> 2.0833333 | N18: =X18/O18 -> 25000000 | O18: 2 | P18: Video | Q18: Sept 1 | R18: Sept 30 | S18: =X18 -> 50000000 | T18: 0.02 | U18: =S18*T18 -> 1000000 | V18: =X18*0.1% -> 50000 | X18: =(Z18*1000)/Y18 -> 50000000 | Y18: 0.7 | Z18: 35000 | AA18: =Z18*3.76 -> 131600
B19: YouTube | C19: Select (Premium Sports Channels) for Official Song Promotion | D19: Song Promotion | E19: KSA | F19: 6s + 15s | G19: CROSS DEVICE | H19: Awareness | I19: CPM | J19: English + Arabic | L19: 19000000 | M19: =N19/L19 -> 0.13157895 | N19: =X19/O19 -> 2500000 | O19: 2 | P19: Video | Q19: Sept 1 | R19: Sept 30 | S19: =X19 -> 5000000 | T19: 0.2 | U19: =S19*T19 -> 1000000 | V19: - | X19: =(Z19*1000)/Y19 -> 5000000 | Y19: 4 | Z19: 20000 | AA19: =Z19*3.76 -> 75200
B20: Programmatic (Anghami) | C20: Song Promotion for official song | D20: Song Promotion | E20: KSA | F20: Custom to the brand Branded Song and Video Clip (if available) including tailored Lyrics, Title and Song Cover | G20: MOBILE | H20: Awareness | I20: Fixed | J20: Arabic | L20: - | M20: - | N20: - | O20: - | P20: Audio | Q20: Sept 1 | R20: Sept 30 | S20: 160000 | T20: - | U20: - | V20: - | X20: - | Y20: Fixed | Z20: 20000 | AA20: =Z20*3.76 -> 75200
B21: Programmatic (TMV) | C21: 3D and AR filters activation for Official Mascot | D21: Mascot Promotion | E21: KSA | F21: Dynamic Ads | G21: CROSS DEVICE | H21: Awareness | I21: CPM | J21: English + Arabic | L21: - | M21: - | N21: - | O21: - | P21: Dynamic Ads | Q21: Sept 1 | R21: Sept 30 | S21: =X21 -> 1250000 | T21: - | U21: - | V21: - | X21: =(Z21*1000)/Y21 -> 1250000 | Y21: 8 | Z21: 10000 | AA21: =Z21*3.76 -> 37600
B22: Total (KSA) | U22: =SUM(U18:U21) -> 2000000 | V22: =SUM(V18:V21) -> 50000 | X22: =SUM(X18:X21) -> 56250000 | Z22: =SUM(Z18:Z21) -> 85000 | AA22: =SUM(AA18:AA21) -> 319600
B24: GCC
B25: Programmatic (Spotify) Song Promotion | C25: Song Promotion for official song | D25: Song Promotion | E25: UAE, Oman, Kuwait, Qatar, Bahrain | F25: Up to 30 Secs Audio file | G25: CROSS DEVICE | H25: Awareness | I25: CPM | J25: Arabic | L25: - | M25: - | N25: - | O25: - | P25: Audio | Q25: Sept 1 | R25: Sept 30 | S25: =X25 -> 2184874 | T25: - | U25: - | V25: - | X25: =(Z25*1000)/Y25 -> 2184874 | Y25: 5.95 | Z25: 13000 | AA25: =Z25*3.76 -> 48880
B26: Programmatic (Spotify) Mascot Promotion - Video | C26: Video Ads | D26: Mascot Promotion | E26: UAE, Oman, Kuwait, Qatar, Bahrain | F26: MOV, MP4 -HD 720x1280 or similar (portrait) -HD 1280x720 or similar (landscape) | G26: CROSS DEVICE | H26: Awareness | I26: CPM | J26: English + Arabic | L26: - | M26: - | N26: - | O26: - | P26: Video | Q26: Sept 1 | R26: Sept 30 | S26: =X26 -> 1111111.1 | T26: - | U26: - | V26: - | X26: =(Z26*1000)/Y26 -> 1111111.1 | Y26: 9 | Z26: 10000 | AA26: =Z26*3.76 -> 37600
B27: Programmatic (Spotify) Mascot Promotion - Display | C27: Dipslay Ads | D27: Mascot Promotion | E27: UAE, Oman, Kuwait, Qatar, Bahrain | F27: At least 600 x 600 pixels (1:1) At least 600 x 500 pixels (6:5) File type: JPEG or PNG | G27: CROSS DEVICE | H27: Awareness | I27: CPM | J27: English + Arabic | L27: - | M27: - | N27: - | O27: - | P27: Display | Q27: Sept 1 | R27: Sept 30 | S27: =X27 -> 4615384.6 | T27: - | U27: - | V27: - | X27: =(Z27*1000)/Y27 -> 4615384.6 | Y27: 1.95 | Z27: 9000 | AA27: =Z27*3.76 -> 33840
B28: Programmatic (TMV) | C28: 3D and AR filters activation for Official Mascot | D28: Mascot Promotion | E28: UAE, Oman, Kuwait, Qatar, Bahrain | F28: Dynamic Ads | G28: CROSS DEVICE | H28: Awareness | I28: CPM | J28: English + Arabic | L28: - | M28: - | N28: - | O28: - | P28: Dynamic Ads | Q28: Sept 1 | R28: Sept 30 | S28: =X28 -> 875000 | T28: - | U28: - | V28: - | X28: =(Z28*1000)/Y28 -> 875000 | Y28: 8 | Z28: 7000 | AA28: =Z28*3.76 -> 26320
B29: Total (GCC) | U29: =SUM(U25:U28) -> 0 | V29: =SUM(V25:V28) -> 0 | X29: =SUM(X25:X28) -> 8786369.7 | Z29: =SUM(Z25:Z28) -> 39000 | AA29: =SUM(AA25:AA28) -> 146640
B31: Iraq
B32: Programmatic (TMV) | C32: 3D and AR filters activation for Official Mascot | D32: Mascot Promotion | E32: Iraq | F32: Dynamic Ads | G32: CROSS DEVICE | H32: Awareness | I32: CPM | J32: English + Arabic | L32: - | M32: - | N32: - | O32: - | P32: Dynamic Ads | Q32: Sept 1 | R32: Sept 30 | S32: =X32 -> 500000 | T32: - | U32: - | V32: - | X32: =(Z32*1000)/Y32 -> 500000 | Y32: 8 | Z32: 4000 | AA32: =Z32*3.76 -> 15040
B33: Total (Iraq) | U33: =SUM(U32) -> 0 | V33: =SUM(V32) -> 0 | X33: =SUM(#REF!) -> #REF! | Z33: =SUM(Z32) -> 4000 | AA33: =SUM(AA32) -> 15040
B36: Grand Total (All Markets) | X36: =SUM(X22,X29) -> 65036370 | Z36: =SUM(Z22,Z29,Z33) -> 128000 | AA36: =SUM(AA22,AA29,AA33) -> 481280
B37: Ad Serving Fees (All Markets) | Z37: 1500 | AA37: =Z37*3.76 -> 5640
B38: Total Media + Ad Serving Fees | Z38: =SUM(Z36:Z37) -> 129500 | AA38: =SUM(AA36:AA37) -> 486920

Sheet FOC - Activations
B6: Client: | C6: LOC
B7: Campaign : | C7: Gulf Cup
B8: Market: | C8: KSA, GCC, Iraq, Yemen
B9: Media: | C9: Digital
B10: reference # | C10: -
B11: PO: | C11: ='[36]Approval Form'!C10 -> #REF!
B12: Date: | C12: =TODAY() -> 46258
B14: PLATFORM | C14: PLACEMENT | D14: OBJECTIVE | E14: Estimated Added Value ( SAR )
B16: TikTok | C16: Feed | D16: Awareness | E16: 26320
B17: YouTube | C17: VRC | D17: Awareness | E17: 25944
B18: Programmatic | C18: Premium sports websites | D18: Website Traffic | E18: 52640
B19: Programmatic (Videx Gaming) | C19: Streamer Mention, Live chat Interaction, Polls, Voting​ Moment Marketing​ Leaderboard​ Innova​ Tower​ | D19: Awareness | E19: 35344
B20: Snapchat | C20: Feed | D20: Awareness | E20: TBC
B21: Total | E21: =SUM(E16:E19) -> 140248

Sheet Targeting
B6: Age:18-55 People who match: Interests: Football, Saudi Soccer League,Association Football, All Soccer fans, Soccer Match Events: Multi Sport Events, Live Matches Behavior: Soccer Fans Medium & High Content Engagement Keywords: Gulf Cup, Soccer, Champions League

Sheet Campaign Phasing
H6: Phase 1 | I6: Song and Mascot Promotion | J6: Phase 2
G7: Market | H7: Aug 1 - Sept 15 | I7: Early September | J7: Sept 16 - Oct 6
G8: KSA | H8: ='Phase 1 - Aug - Sept (Launch)'!Y30 -> 270363 | I8: ='Song and Mascot Promotion'!Z22 -> 85000 | J8: ='Phase 2 - Sep - Oct'!Y29 -> 192000 | K8: =SUM(H8:J8) -> 547363 | L8: =K8/$K$12 -> 0.74627214
G9: GCC | H9: ='Phase 1 - Aug - Sept (Launch)'!Y37 -> 55000 | I9: ='Song and Mascot Promotion'!Z29 -> 39000 | J9: ='Phase 2 - Sep - Oct'!Y36 -> 28000 | K9: =SUM(H9:J9) -> 122000 | L9: =K9/$K$12 -> 0.16633423
G10: Iraq | H10: ='Phase 1 - Aug - Sept (Launch)'!Y43 -> 17000 | I10: ='Song and Mascot Promotion'!Z33 -> 4000 | J10: ='Phase 2 - Sep - Oct'!Y43 -> 17500 | K10: =SUM(H10:J10) -> 38500 | L10: =K10/$K$12 -> 0.052490719
G11: Yemen | H11: ='Phase 1 - Aug - Sept (Launch)'!Y49 -> 15600 | I11: - | J11: ='Phase 2 - Sep - Oct'!Y49 -> 10000 | K11: =SUM(H11:J11) -> 25600 | L11: =K11/$K$12 -> 0.034902919
G12: Total | H12: =SUM(H8:H11) -> 357963 | I12: =SUM(I8:I11) -> 128000 | J12: =SUM(J8:J11) -> 247500 | K12: =SUM(H12:J12) -> 733463 | L12: =SUM(L8:L11) -> 1
H13: =H12*3.76 -> 1345940.9 | I13: =I12*3.76 -> 481280 | J13: =J12*3.76 -> 930600 | K13: =SUM(H13:J13) -> 2757820.9
H14: =H13/$K$13 -> 0.48804507 | I14: =I13/$K$13 -> 0.1745146 | J14: =J13/$K$13 -> 0.33744033 | K14: =SUM(H14:J14) -> 1

Sheet Budgeting - Phase
G8: Phase | H8: Market | I8: Budget | J8: Phase Budget % | K8: Total Budget % | L8: Budget ($)
G10: Phase 1 - Aug - Sept (Launch) | H10: KSA | I10: ='Campaign Phasing'!H8*3.76 -> 1016564.9 | J10: =I10/$I$14 -> 0.75528197 | K10: =I10/$I$28 -> 0.36861164 | L10: =I10/3.76 -> 270363
H11: GCC | I11: ='Campaign Phasing'!H9*3.76 -> 206800 | J11: =I11/$I$14 -> 0.15364716 | K11: =I11/$I$28 -> 0.074986741 | L11: =I11/3.76 -> 55000
H12: Iraq | I12: ='Campaign Phasing'!H10*3.76 -> 63920 | J12: =I12/$I$14 -> 0.047490942 | K12: =I12/$I$28 -> 0.02317772 | L12: =I12/3.76 -> 17000
H13: Yemen | I13: ='Campaign Phasing'!H11*3.76 -> 58656 | J13: =I13/$I$14 -> 0.043579923 | K13: =I13/$I$28 -> 0.021268967 | L13: =I13/3.76 -> 15600
G14: Phase 1 - Aug - Sept (Launch) | I14: =SUM(I10:I13) -> 1345940.9 | J14: =SUM(J10:J13) -> 1 | K14: =I14/$I$28 -> 0.48804507 | L14: =SUM(L10:L13) -> 357963
G16: Song and Mascot Promotion | H16: KSA | I16: ='Campaign Phasing'!I8*3.76 -> 319600 | J16: =I16/$I$19 -> 0.6640625 | K16: =I16/$I$28 -> 0.1158886 | L16: =I16/3.76 -> 85000
H17: GCC | I17: ='Campaign Phasing'!I9*3.76 -> 146640 | J17: =I17/$I$19 -> 0.3046875 | K17: =I17/$I$28 -> 0.053172416 | L17: =I17/3.76 -> 39000
H18: Iraq | I18: ='Campaign Phasing'!I10*3.76 -> 15040 | J18: =I18/$I$19 -> 0.03125 | K18: =I18/$I$28 -> 0.0054535812 | L18: =I18/3.76 -> 4000
G19: Song and Mascot Promotion | I19: =SUM(I16:I18) -> 481280 | J19: =SUM(J16:J18) -> 1 | K19: =I19/$I$28 -> 0.1745146 | L19: =SUM(L16:L18) -> 128000
G21: Phase 2 - Sep - Oct | H21: KSA | I21: ='Campaign Phasing'!J8*3.76 -> 721920 | J21: =I21/$I$25 -> 0.77575758 | K21: =I21/$I$28 -> 0.2617719 | L21: =I21/3.76 -> 192000
H22: GCC | I22: ='Campaign Phasing'!J9*3.76 -> 105280 | J22: =I22/$I$25 -> 0.11313131 | K22: =I22/$I$28 -> 0.038175068 | L22: =I22/3.76 -> 28000
H23: Iraq | I23: ='Campaign Phasing'!J10*3.76 -> 65800 | J23: =I23/$I$25 -> 0.070707071 | K23: =I23/$I$28 -> 0.023859418 | L23: =I23/3.76 -> 17500
H24: Yemen | I24: ='Campaign Phasing'!J11*3.76 -> 37600 | J24: =I24/$I$25 -> 0.04040404 | K24: =I24/$I$28 -> 0.013633953 | L24: =I24/3.76 -> 10000
G25: Phase 2 - Sep - Oct | I25: =SUM(I21:I24) -> 930600 | J25: =SUM(J21:J24) -> 1 | K25: =I25/$I$28 -> 0.33744033 | L25: =SUM(L21:L24) -> 247500
G28: Grand Total | I28: =SUM(I14,I19,I25) -> 2757820.9 | L28: =SUM(L14,L19,L25) -> 733463

Sheet Budgeting - Channel
G4: Phase | H4: Market | I4: Channel | J4: Budget ($) | K4: Budget (SAR)
G5: Phase 1 - Aug - Sept | H5: KSA | I5: ='Phase 1 - Aug - Sept (Launch)'!B18 -> META | J5: ='Phase 1 - Aug - Sept (Launch)'!Y18 -> 16000 | K5: =J5*3.76 -> 60160
G6: Phase 1 - Aug - Sept | H6: KSA | I6: ='Phase 1 - Aug - Sept (Launch)'!B19 -> TikTok | J6: ='Phase 1 - Aug - Sept (Launch)'!Y19 -> 18720 | K6: =J6*3.76 -> 70387.2
G7: Phase 1 - Aug - Sept | H7: KSA | I7: ='Phase 1 - Aug - Sept (Launch)'!B20 -> Snapchat | J7: ='Phase 1 - Aug - Sept (Launch)'!Y20 -> 17150 | K7: =J7*3.76 -> 64484
G8: Phase 1 - Aug - Sept | H8: KSA | I8: ='Phase 1 - Aug - Sept (Launch)'!B21 -> Snapchat First Commercial Takeover | J8: ='Phase 1 - Aug - Sept (Launch)'!Y21 -> 17000 | K8: =J8*3.76 -> 63920
G9: Phase 1 - Aug - Sept | H9: KSA | I9: ='Phase 1 - Aug - Sept (Launch)'!B22 -> X | J9: ='Phase 1 - Aug - Sept (Launch)'!Y22 -> 15000 | K9: =J9*3.76 -> 56400
G10: Phase 1 - Aug - Sept | H10: KSA | I10: ='Phase 1 - Aug - Sept (Launch)'!B23 -> X Takeover | J10: ='Phase 1 - Aug - Sept (Launch)'!Y23 -> 58493 | K10: =J10*3.76 -> 219933.68
G11: Phase 1 - Aug - Sept | H11: KSA | I11: ='Phase 1 - Aug - Sept (Launch)'!B24 -> YouTube | J11: ='Phase 1 - Aug - Sept (Launch)'!Y24 -> 25000 | K11: =J11*3.76 -> 94000
G12: Phase 1 - Aug - Sept | H12: KSA | I12: ='Phase 1 - Aug - Sept (Launch)'!B25 -> Programmatic | J12: ='Phase 1 - Aug - Sept (Launch)'!Y25 -> 45000 | K12: =J12*3.76 -> 169200
G13: Phase 1 - Aug - Sept | H13: KSA | I13: ='Phase 1 - Aug - Sept (Launch)'!B26 -> Google Search | J13: ='Phase 1 - Aug - Sept (Launch)'!Y26 -> 7000 | K13: =J13*3.76 -> 26320
G14: Phase 1 - Aug - Sept | H14: KSA | I14: ='Phase 1 - Aug - Sept (Launch)'!B27 -> Google Pmax | J14: ='Phase 1 - Aug - Sept (Launch)'!Y27 -> 11000 | K14: =J14*3.76 -> 41360
G15: Phase 1 - Aug - Sept | H15: KSA | I15: ='Phase 1 - Aug - Sept (Launch)'!B28 -> META | J15: ='Phase 1 - Aug - Sept (Launch)'!Y28 -> 20000 | K15: =J15*3.76 -> 75200
G16: Phase 1 - Aug - Sept | H16: KSA | I16: ='Phase 1 - Aug - Sept (Launch)'!B29 -> TikTok | J16: ='Phase 1 - Aug - Sept (Launch)'!Y29 -> 20000 | K16: =J16*3.76 -> 75200
G17: Phase 1 - Aug - Sept | H17: GCC | I17: ='Phase 1 - Aug - Sept (Launch)'!B33 -> META | J17: ='Phase 1 - Aug - Sept (Launch)'!Y33 -> 15000 | K17: =J17*3.76 -> 56400
G18: Phase 1 - Aug - Sept | H18: GCC | I18: ='Phase 1 - Aug - Sept (Launch)'!B34 -> YouTube | J18: ='Phase 1 - Aug - Sept (Launch)'!Y34 -> 14000 | K18: =J18*3.76 -> 52640
G19: Phase 1 - Aug - Sept | H19: GCC | I19: ='Phase 1 - Aug - Sept (Launch)'!B35 -> Programmatic | J19: ='Phase 1 - Aug - Sept (Launch)'!Y35 -> 14000 | K19: =J19*3.76 -> 52640
G20: Phase 1 - Aug - Sept | H20: GCC | I20: ='Phase 1 - Aug - Sept (Launch)'!B36 -> Google Pmax | J20: ='Phase 1 - Aug - Sept (Launch)'!Y36 -> 12000 | K20: =J20*3.76 -> 45120
G21: Phase 1 - Aug - Sept | H21: Iraq | I21: ='Phase 1 - Aug - Sept (Launch)'!B40 -> META | J21: ='Phase 1 - Aug - Sept (Launch)'!Y40 -> 5000 | K21: =J21*3.76 -> 18800
G22: Phase 1 - Aug - Sept | H22: Iraq | I22: ='Phase 1 - Aug - Sept (Launch)'!B41 -> YouTube | J22: ='Phase 1 - Aug - Sept (Launch)'!Y41 -> 7000 | K22: =J22*3.76 -> 26320
G23: Phase 1 - Aug - Sept | H23: Iraq | I23: ='Phase 1 - Aug - Sept (Launch)'!B42 -> Google Pmax | J23: ='Phase 1 - Aug - Sept (Launch)'!Y42 -> 5000 | K23: =J23*3.76 -> 18800
G24: Phase 1 - Aug - Sept | H24: Yemen | I24: ='Phase 1 - Aug - Sept (Launch)'!B46 -> META | J24: ='Phase 1 - Aug - Sept (Launch)'!Y46 -> 5600 | K24: =J24*3.76 -> 21056
G25: Phase 1 - Aug - Sept | H25: Yemen | I25: ='Phase 1 - Aug - Sept (Launch)'!B47 -> YouTube | J25: ='Phase 1 - Aug - Sept (Launch)'!Y47 -> 4000 | K25: =J25*3.76 -> 15040
G26: Phase 1 - Aug - Sept | H26: Yemen | I26: ='Phase 1 - Aug - Sept (Launch)'!B48 -> Google Pmax | J26: ='Phase 1 - Aug - Sept (Launch)'!Y48 -> 6000 | K26: =J26*3.76 -> 22560
G27: Song and Mascot Promotion | H27: KSA | I27: ='Song and Mascot Promotion'!B18 -> Snapchat | J27: ='Song and Mascot Promotion'!Z18 -> 35000 | K27: =J27*3.76 -> 131600
G28: Song and Mascot Promotion | H28: KSA | I28: ='Song and Mascot Promotion'!B19 -> YouTube | J28: ='Song and Mascot Promotion'!Z19 -> 20000 | K28: =J28*3.76 -> 75200
G29: Song and Mascot Promotion | H29: KSA | I29: ='Song and Mascot Promotion'!B20 -> Programmatic (Anghami) | J29: ='Song and Mascot Promotion'!Z20 -> 20000 | K29: =J29*3.76 -> 75200
G30: Song and Mascot Promotion | H30: KSA | I30: ='Song and Mascot Promotion'!B21 -> Programmatic (TMV) | J30: ='Song and Mascot Promotion'!Z21 -> 10000 | K30: =J30*3.76 -> 37600
G31: Song and Mascot Promotion | H31: GCC | I31: ='Song and Mascot Promotion'!B25 -> Programmatic (Spotify) Song Promotion | J31: ='Song and Mascot Promotion'!Z25 -> 13000 | K31: =J31*3.76 -> 48880
G32: Song and Mascot Promotion | H32: GCC | I32: ='Song and Mascot Promotion'!B26 -> Programmatic (Spotify) Mascot Promotion - Video | J32: ='Song and Mascot Promotion'!Z26 -> 10000 | K32: =J32*3.76 -> 37600
G33: Song and Mascot Promotion | H33: GCC | I33: ='Song and Mascot Promotion'!B27 -> Programmatic (Spotify) Mascot Promotion - Display | J33: ='Song and Mascot Promotion'!Z27 -> 9000 | K33: =J33*3.76 -> 33840
G34: Song and Mascot Promotion | H34: GCC | I34: ='Song and Mascot Promotion'!B28 -> Programmatic (TMV) | J34: ='Song and Mascot Promotion'!Z28 -> 7000 | K34: =J34*3.76 -> 26320
G35: Song and Mascot Promotion | H35: Iraq | I35: ='Song and Mascot Promotion'!B32 -> Programmatic (TMV) | J35: ='Song and Mascot Promotion'!Z32 -> 4000 | K35: =J35*3.76 -> 15040
G36: Phase 2 - Sep - Oct | H36: KSA | I36: ='Phase 2 - Sep - Oct'!B18 -> META | J36: ='Phase 2 - Sep - Oct'!Y18 -> 18000 | K36: =J36*3.76 -> 67680
G37: Phase 2 - Sep - Oct | H37: KSA | I37: ='Phase 2 - Sep - Oct'!B19 -> TikTok | J37: ='Phase 2 - Sep - Oct'!Y19 -> 18000 | K37: =J37*3.76 -> 67680
G38: Phase 2 - Sep - Oct | H38: KSA | I38: ='Phase 2 - Sep - Oct'!B20 -> Snapchat | J38: ='Phase 2 - Sep - Oct'!Y20 -> 18000 | K38: =J38*3.76 -> 67680
G39: Phase 2 - Sep - Oct | H39: KSA | I39: ='Phase 2 - Sep - Oct'!B21 -> YouTube | J39: ='Phase 2 - Sep - Oct'!Y21 -> 18000 | K39: =J39*3.76 -> 67680
G40: Phase 2 - Sep - Oct | H40: KSA | I40: ='Phase 2 - Sep - Oct'!B22 -> Programmatic | J40: ='Phase 2 - Sep - Oct'!Y22 -> 40000 | K40: =J40*3.76 -> 150400
G41: Phase 2 - Sep - Oct | H41: KSA | I41: ='Phase 2 - Sep - Oct'!B23 -> X | J41: ='Phase 2 - Sep - Oct'!Y23 -> 16000 | K41: =J41*3.76 -> 60160
G42: Phase 2 - Sep - Oct | H42: KSA | I42: ='Phase 2 - Sep - Oct'!B24 -> Programmatic (Videx Gaming) | J42: ='Phase 2 - Sep - Oct'!Y24 -> 14000 | K42: =J42*3.76 -> 52640
G43: Phase 2 - Sep - Oct | H43: KSA | I43: ='Phase 2 - Sep - Oct'!B25 -> Google | J43: ='Phase 2 - Sep - Oct'!Y25 -> 12000 | K43: =J43*3.76 -> 45120
...

Sheet Sheet9
L24: Row Labels | M24: Sum of Budget ($) | N24: Sum of Budget (SAR)
L25: Phase 1 Teaser | M25: 24000 | N25: 90240 | O25: =N25/$N$31 -> 0.031683168
L26: Phase 2 - May 2026 | M26: 117000 | N26: 439920 | O26: =N26/$N$31 -> 0.15445545
L27: Phase 3 - June 2026 | M27: 60000 | N27: 225600 | O27: =N27/$N$31 -> 0.079207921
L28: Phase 4 - July 2026 | M28: 85000 | N28: 319600 | O28: =N28/$N$31 -> 0.11221122
L29: Phase 5 - Aug - Sept | M29: 240000 | N29: 902400 | O29: =N29/$N$31 -> 0.31683168
L30: Phase 6 - Sept - Oct | M30: 231500 | N30: 870440 | O30: =N30/$N$31 -> 0.30561056
L31: Grand Total | M31: 757500 | N31: 2848200
